<?xml version="1.0" encoding="UTF-8"?>
<testng-results ignored="0" total="7" passed="4" failed="3" skipped="0">
  <reporter-output>
  </reporter-output>
  <suite started-at="2022-09-19T13:31:17 IST" name="Suite1" finished-at="2022-09-19T13:31:47 IST" duration-ms="30252">
    <groups>
    </groups>
    <test started-at="2022-09-19T13:31:17 IST" name="Test1" finished-at="2022-09-19T13:31:47 IST" duration-ms="30252">
      <class name="appiumtests.merchantApp_testNG">
        <test-method is-config="true" signature="merchantAppDirectOrder()[pri:0, instance:appiumtests.merchantApp_testNG@470f1802]" started-at="2022-09-19T13:31:17 IST" name="merchantAppDirectOrder" finished-at="2022-09-19T13:31:22 IST" duration-ms="5428" status="PASS">
          <reporter-output>
          </reporter-output>
        </test-method> <!-- merchantAppDirectOrder -->
        <test-method signature="email()[pri:1, instance:appiumtests.merchantApp_testNG@470f1802]" started-at="2022-09-19T13:31:23 IST" name="email" finished-at="2022-09-19T13:31:32 IST" duration-ms="9760" status="PASS">
          <reporter-output>
          </reporter-output>
        </test-method> <!-- email -->
        <test-method signature="clickNextEmail()[pri:2, instance:appiumtests.merchantApp_testNG@470f1802]" started-at="2022-09-19T13:31:32 IST" name="clickNextEmail" finished-at="2022-09-19T13:31:33 IST" duration-ms="786" status="PASS">
          <reporter-output>
          </reporter-output>
        </test-method> <!-- clickNextEmail -->
        <test-method signature="enterPassword()[pri:3, instance:appiumtests.merchantApp_testNG@470f1802]" started-at="2022-09-19T13:31:33 IST" name="enterPassword" finished-at="2022-09-19T13:31:47 IST" duration-ms="14154" status="PASS">
          <reporter-output>
          </reporter-output>
        </test-method> <!-- enterPassword -->
        <test-method signature="failTest1()[pri:4, instance:appiumtests.merchantApp_testNG@470f1802]" started-at="2022-09-19T13:31:47 IST" name="failTest1" finished-at="2022-09-19T13:31:47 IST" duration-ms="22" status="FAIL">
          <exception class="java.lang.AssertionError">
            <message>
              <![CDATA[expected [1234] but found [123]]]>
            </message>
            <full-stacktrace>
              <![CDATA[java.lang.AssertionError: expected [1234] but found [123]
at org.testng.Assert.fail(Assert.java:110)
at org.testng.Assert.failNotEquals(Assert.java:1413)
at org.testng.Assert.assertEqualsImpl(Assert.java:149)
at org.testng.Assert.assertEquals(Assert.java:131)
at org.testng.Assert.assertEquals(Assert.java:655)
at org.testng.Assert.assertEquals(Assert.java:665)
at appiumtests.merchantApp_testNG.failTest1(merchantApp_testNG.java:82)
at java.base/jdk.internal.reflect.NativeMethodAccessorImpl.invoke0(Native Method)
at java.base/jdk.internal.reflect.NativeMethodAccessorImpl.invoke(NativeMethodAccessorImpl.java:78)
at java.base/jdk.internal.reflect.DelegatingMethodAccessorImpl.invoke(DelegatingMethodAccessorImpl.java:43)
at java.base/java.lang.reflect.Method.invoke(Method.java:567)
at org.testng.internal.invokers.MethodInvocationHelper.invokeMethod(MethodInvocationHelper.java:139)
at org.testng.internal.invokers.TestInvoker.invokeMethod(TestInvoker.java:677)
at org.testng.internal.invokers.TestInvoker.invokeTestMethod(TestInvoker.java:221)
at org.testng.internal.invokers.MethodRunner.runInSequence(MethodRunner.java:50)
at org.testng.internal.invokers.TestInvoker$MethodInvocationAgent.invoke(TestInvoker.java:962)
at org.testng.internal.invokers.TestInvoker.invokeTestMethods(TestInvoker.java:194)
at org.testng.internal.invokers.TestMethodWorker.invokeTestMethods(TestMethodWorker.java:148)
at org.testng.internal.invokers.TestMethodWorker.run(TestMethodWorker.java:128)
at java.base/java.util.ArrayList.forEach(ArrayList.java:1511)
at org.testng.TestRunner.privateRun(TestRunner.java:806)
at org.testng.TestRunner.run(TestRunner.java:601)
at org.testng.SuiteRunner.runTest(SuiteRunner.java:433)
at org.testng.SuiteRunner.runSequentially(SuiteRunner.java:427)
at org.testng.SuiteRunner.privateRun(SuiteRunner.java:387)
at org.testng.SuiteRunner.run(SuiteRunner.java:330)
at org.testng.SuiteRunnerWorker.runSuite(SuiteRunnerWorker.java:52)
at org.testng.SuiteRunnerWorker.run(SuiteRunnerWorker.java:95)
at org.testng.TestNG.runSuitesSequentially(TestNG.java:1256)
at org.testng.TestNG.runSuitesLocally(TestNG.java:1176)
at org.testng.TestNG.runSuites(TestNG.java:1099)
at org.testng.TestNG.run(TestNG.java:1067)
at org.apache.maven.surefire.testng.TestNGExecutor.run(TestNGExecutor.java:324)
at org.apache.maven.surefire.testng.TestNGXmlTestSuite.execute(TestNGXmlTestSuite.java:74)
at org.apache.maven.surefire.testng.TestNGProvider.invoke(TestNGProvider.java:123)
at org.apache.maven.surefire.booter.ForkedBooter.runSuitesInProcess(ForkedBooter.java:456)
at org.apache.maven.surefire.booter.ForkedBooter.execute(ForkedBooter.java:169)
at org.apache.maven.surefire.booter.ForkedBooter.run(ForkedBooter.java:595)
at org.apache.maven.surefire.booter.ForkedBooter.main(ForkedBooter.java:581)
]]>
            </full-stacktrace>
          </exception> <!-- java.lang.AssertionError -->
          <reporter-output>
          </reporter-output>
        </test-method> <!-- failTest1 -->
        <test-method signature="failTest2()[pri:5, instance:appiumtests.merchantApp_testNG@470f1802]" started-at="2022-09-19T13:31:47 IST" name="failTest2" finished-at="2022-09-19T13:31:47 IST" duration-ms="11" status="FAIL">
          <exception class="java.lang.AssertionError">
            <message>
              <![CDATA[expected [12345] but found [1234]]]>
            </message>
            <full-stacktrace>
              <![CDATA[java.lang.AssertionError: expected [12345] but found [1234]
at org.testng.Assert.fail(Assert.java:110)
at org.testng.Assert.failNotEquals(Assert.java:1413)
at org.testng.Assert.assertEqualsImpl(Assert.java:149)
at org.testng.Assert.assertEquals(Assert.java:131)
at org.testng.Assert.assertEquals(Assert.java:655)
at org.testng.Assert.assertEquals(Assert.java:665)
at appiumtests.merchantApp_testNG.failTest2(merchantApp_testNG.java:106)
at java.base/jdk.internal.reflect.NativeMethodAccessorImpl.invoke0(Native Method)
at java.base/jdk.internal.reflect.NativeMethodAccessorImpl.invoke(NativeMethodAccessorImpl.java:78)
at java.base/jdk.internal.reflect.DelegatingMethodAccessorImpl.invoke(DelegatingMethodAccessorImpl.java:43)
at java.base/java.lang.reflect.Method.invoke(Method.java:567)
at org.testng.internal.invokers.MethodInvocationHelper.invokeMethod(MethodInvocationHelper.java:139)
at org.testng.internal.invokers.TestInvoker.invokeMethod(TestInvoker.java:677)
at org.testng.internal.invokers.TestInvoker.invokeTestMethod(TestInvoker.java:221)
at org.testng.internal.invokers.MethodRunner.runInSequence(MethodRunner.java:50)
at org.testng.internal.invokers.TestInvoker$MethodInvocationAgent.invoke(TestInvoker.java:962)
at org.testng.internal.invokers.TestInvoker.invokeTestMethods(TestInvoker.java:194)
at org.testng.internal.invokers.TestMethodWorker.invokeTestMethods(TestMethodWorker.java:148)
at org.testng.internal.invokers.TestMethodWorker.run(TestMethodWorker.java:128)
at java.base/java.util.ArrayList.forEach(ArrayList.java:1511)
at org.testng.TestRunner.privateRun(TestRunner.java:806)
at org.testng.TestRunner.run(TestRunner.java:601)
at org.testng.SuiteRunner.runTest(SuiteRunner.java:433)
at org.testng.SuiteRunner.runSequentially(SuiteRunner.java:427)
at org.testng.SuiteRunner.privateRun(SuiteRunner.java:387)
at org.testng.SuiteRunner.run(SuiteRunner.java:330)
at org.testng.SuiteRunnerWorker.runSuite(SuiteRunnerWorker.java:52)
at org.testng.SuiteRunnerWorker.run(SuiteRunnerWorker.java:95)
at org.testng.TestNG.runSuitesSequentially(TestNG.java:1256)
at org.testng.TestNG.runSuitesLocally(TestNG.java:1176)
at org.testng.TestNG.runSuites(TestNG.java:1099)
at org.testng.TestNG.run(TestNG.java:1067)
at org.apache.maven.surefire.testng.TestNGExecutor.run(TestNGExecutor.java:324)
at org.apache.maven.surefire.testng.TestNGXmlTestSuite.execute(TestNGXmlTestSuite.java:74)
at org.apache.maven.surefire.testng.TestNGProvider.invoke(TestNGProvider.java:123)
at org.apache.maven.surefire.booter.ForkedBooter.runSuitesInProcess(ForkedBooter.java:456)
at org.apache.maven.surefire.booter.ForkedBooter.execute(ForkedBooter.java:169)
at org.apache.maven.surefire.booter.ForkedBooter.run(ForkedBooter.java:595)
at org.apache.maven.surefire.booter.ForkedBooter.main(ForkedBooter.java:581)
]]>
            </full-stacktrace>
          </exception> <!-- java.lang.AssertionError -->
          <reporter-output>
          </reporter-output>
        </test-method> <!-- failTest2 -->
        <test-method signature="failTest3()[pri:6, instance:appiumtests.merchantApp_testNG@470f1802]" started-at="2022-09-19T13:31:47 IST" name="failTest3" finished-at="2022-09-19T13:31:47 IST" duration-ms="11" status="FAIL">
          <exception class="java.lang.AssertionError">
            <message>
              <![CDATA[expected [12345] but found [1234aa]]]>
            </message>
            <full-stacktrace>
              <![CDATA[java.lang.AssertionError: expected [12345] but found [1234aa]
at org.testng.Assert.fail(Assert.java:110)
at org.testng.Assert.failNotEquals(Assert.java:1413)
at org.testng.Assert.assertEqualsImpl(Assert.java:149)
at org.testng.Assert.assertEquals(Assert.java:131)
at org.testng.Assert.assertEquals(Assert.java:655)
at org.testng.Assert.assertEquals(Assert.java:665)
at appiumtests.merchantApp_testNG.failTest3(merchantApp_testNG.java:115)
at java.base/jdk.internal.reflect.NativeMethodAccessorImpl.invoke0(Native Method)
at java.base/jdk.internal.reflect.NativeMethodAccessorImpl.invoke(NativeMethodAccessorImpl.java:78)
at java.base/jdk.internal.reflect.DelegatingMethodAccessorImpl.invoke(DelegatingMethodAccessorImpl.java:43)
at java.base/java.lang.reflect.Method.invoke(Method.java:567)
at org.testng.internal.invokers.MethodInvocationHelper.invokeMethod(MethodInvocationHelper.java:139)
at org.testng.internal.invokers.TestInvoker.invokeMethod(TestInvoker.java:677)
at org.testng.internal.invokers.TestInvoker.invokeTestMethod(TestInvoker.java:221)
at org.testng.internal.invokers.MethodRunner.runInSequence(MethodRunner.java:50)
at org.testng.internal.invokers.TestInvoker$MethodInvocationAgent.invoke(TestInvoker.java:962)
at org.testng.internal.invokers.TestInvoker.invokeTestMethods(TestInvoker.java:194)
at org.testng.internal.invokers.TestMethodWorker.invokeTestMethods(TestMethodWorker.java:148)
at org.testng.internal.invokers.TestMethodWorker.run(TestMethodWorker.java:128)
at java.base/java.util.ArrayList.forEach(ArrayList.java:1511)
at org.testng.TestRunner.privateRun(TestRunner.java:806)
at org.testng.TestRunner.run(TestRunner.java:601)
at org.testng.SuiteRunner.runTest(SuiteRunner.java:433)
at org.testng.SuiteRunner.runSequentially(SuiteRunner.java:427)
at org.testng.SuiteRunner.privateRun(SuiteRunner.java:387)
at org.testng.SuiteRunner.run(SuiteRunner.java:330)
at org.testng.SuiteRunnerWorker.runSuite(SuiteRunnerWorker.java:52)
at org.testng.SuiteRunnerWorker.run(SuiteRunnerWorker.java:95)
at org.testng.TestNG.runSuitesSequentially(TestNG.java:1256)
at org.testng.TestNG.runSuitesLocally(TestNG.java:1176)
at org.testng.TestNG.runSuites(TestNG.java:1099)
at org.testng.TestNG.run(TestNG.java:1067)
at org.apache.maven.surefire.testng.TestNGExecutor.run(TestNGExecutor.java:324)
at org.apache.maven.surefire.testng.TestNGXmlTestSuite.execute(TestNGXmlTestSuite.java:74)
at org.apache.maven.surefire.testng.TestNGProvider.invoke(TestNGProvider.java:123)
at org.apache.maven.surefire.booter.ForkedBooter.runSuitesInProcess(ForkedBooter.java:456)
at org.apache.maven.surefire.booter.ForkedBooter.execute(ForkedBooter.java:169)
at org.apache.maven.surefire.booter.ForkedBooter.run(ForkedBooter.java:595)
at org.apache.maven.surefire.booter.ForkedBooter.main(ForkedBooter.java:581)
]]>
            </full-stacktrace>
          </exception> <!-- java.lang.AssertionError -->
          <reporter-output>
          </reporter-output>
        </test-method> <!-- failTest3 -->
        <test-method signature="failTest5()[pri:6, instance:appiumtests.merchantApp_testNG@470f1802]" started-at="2022-09-19T13:31:47 IST" name="failTest5" finished-at="2022-09-19T13:31:47 IST" duration-ms="10" status="PASS">
          <reporter-output>
          </reporter-output>
        </test-method> <!-- failTest5 -->
        <test-method is-config="true" signature="teardownTest()[pri:0, instance:appiumtests.merchantApp_testNG@470f1802]" started-at="2022-09-19T13:31:47 IST" name="teardownTest" finished-at="2022-09-19T13:31:47 IST" duration-ms="0" status="PASS">
          <reporter-output>
          </reporter-output>
        </test-method> <!-- teardownTest -->
      </class> <!-- appiumtests.merchantApp_testNG -->
    </test> <!-- Test1 -->
  </suite> <!-- Suite1 -->
</testng-results>
